Workbook

Sheet Raw_data
A1: Order ID | B1: Order Date | C1: Customer ID | D1: Type | E1: SKU | F1: Category | G1: Product Name | H1: Unit Price | I1: Qty | J1: Total | K1: Discount Code | L1: Disc % | M1: Payment | N1: Source | O1: City | P1: State | Q1: Warehouse | R1: Del Date | S1: Status | T1: Return? | U1: Reason | V1: Ret Rec | W1: Refund | X1: valid_quantity_flag | Y1: Discount_amount | Z1: Net revenue | AA1: Average order value | AB1: Order_month | AC1: Order_week | AD1: Payment Type
A2: UT-100001 | B2: 45566 | C2: CUST_10001 | D2: New | E2: TOP-CAS-M | F2: Tops | G2: Classic Cotton Tee | H2: 1299 | I2: 2 | J2: 2598 | L2: 0 | M2: UPI | N2: Website | O2: Mumbai | P2: Maharashtra | Q2: Mumbai | R2: 45570 | S2: Delivered | T2: No | W2: Not Applicable | X2: =IF(urbanthreads_q4[[#This Row],[Qty]]>0,"Valid","Invalid") -> Valid | Y2: =urbanthreads_q4[[#This Row],[Total]]*urbanthreads_q4[[#This Row],[Disc %]]/100 -> 0 | Z2: =urbanthreads_q4[[#This Row],[Total]]-urbanthreads_q4[[#This Row],[Disc %]] -> 2598 | AA2: =urbanthreads_q4[[#This Row],[Net revenue]]/urbanthreads_q4[[#This Row],[Total]] -> 1 | AB2: =TEXT(urbanthreads_q4[[#This Row],[Order Date]],"mm-yyyy") -> 10-2024 | AC2: =YEAR(urbanthreads_q4[[#This Row],[Order Date]]) & "-W" & WEEKNUM(urbanthreads_q4[[#This Row],[Order Date]], 2) -> 2024-W40 | AD2: =IF(urbanthreads_q4[[#This Row],[Payment]]="COD","COD","Prepaid") -> Prepaid
A3: UT-100343 | B3: 45656 | C3: CUST_10342 | D3: New | E3: OUT-FRE-M | F3: Outerwear | G3: Fresh Start Jacket | H3: 4899 | I3: 1 | J3: 4899 | K3: Dec20 | L3: 20 | M3: COD | N3: Website | O3: Mumbai | P3: Maharashtra | Q3: Mumbai | R3: 45684 | S3: Delivered | T3: Yes | U3: Wrong Item | V3: 45712 | W3: Processed | X3: =IF(urbanthreads_q4[[#This Row],[Qty]]>0,"Valid","Invalid") -> Valid | Y3: =urbanthreads_q4[[#This Row],[Total]]*urbanthreads_q4[[#This Row],[Disc %]]/100 -> 979.8 | Z3: =urbanthreads_q4[[#This Row],[Total]]-urbanthreads_q4[[#This Row],[Disc %]] -> 4879 | AA3: =urbanthreads_q4[[#This Row],[Net revenue]]/urbanthreads_q4[[#This Row],[Total]] -> 0.99591753 | AB3: =TEXT(urbanthreads_q4[[#This Row],[Order Date]],"mm-yyyy") -> 12-2024 | AC3: =YEAR(urbanthreads_q4[[#This Row],[Order Date]]) & "-W" & WEEKNUM(urbanthreads_q4[[#This Row],[Order Date]], 2) -> 2024-W53 | AD3: =IF(urbanthreads_q4[[#This Row],[Payment]]="COD","COD","Prepaid") -> COD
A4: UT-100003 | B4: 45301 | C4: CUST_10003 | D4: new | E4: BOT-JNS-L | F4: Bottoms | G4: Slim Fit Jeans | H4: 1899 | I4: 1 | J4: 1899 | L4: 0 | M4: COD | N4: Website | O4: Bangalore | P4: Karnataka | Q4: Bangalore | R4: 45571 | S4: Delivered | T4: No | W4: Not Applicable | X4: =IF(urbanthreads_q4[[#This Row],[Qty]]>0,"Valid","Invalid") -> Valid | Y4: =urbanthreads_q4[[#This Row],[Total]]*urbanthreads_q4[[#This Row],[Disc %]]/100 -> 0 | Z4: =urbanthreads_q4[[#This Row],[Total]]-urbanthreads_q4[[#This Row],[Disc %]] -> 1899 | AA4: =urbanthreads_q4[[#This Row],[Net revenue]]/urbanthreads_q4[[#This Row],[Total]] -> 1 | AB4: =TEXT(urbanthreads_q4[[#This Row],[Order Date]],"mm-yyyy") -> 01-2024 | AC4: =YEAR(urbanthreads_q4[[#This Row],[Order Date]]) & "-W" & WEEKNUM(urbanthreads_q4[[#This Row],[Order Date]], 2) -> 2024-W2 | AD4: =IF(urbanthreads_q4[[#This Row],[Payment]]="COD","COD","Prepaid") -> COD
A5: UT-100345 | B5: 45656 | C5: CUST_10344 | D5: New | E5: TOP-BEG-L | F5: Tops | G5: Begin Again Top | H5: 2199 | I5: 1 | J5: 2199 | L5: 0 | M5: Debit Card | N5: Instagram Shop | O5: Chandigarh | P5: Punjab | Q5: Delhi | R5: 45684 | S5: Delivered | T5: Yes | U5: Damaged in Transit | V5: 45711 | W5: Processed | X5: =IF(urbanthreads_q4[[#This Row],[Qty]]>0,"Valid","Invalid") -> Valid | Y5: =urbanthreads_q4[[#This Row],[Total]]*urbanthreads_q4[[#This Row],[Disc %]]/100 -> 0 | Z5: =urbanthreads_q4[[#This Row],[Total]]-urbanthreads_q4[[#This Row],[Disc %]] -> 2199 | AA5: =urbanthreads_q4[[#This Row],[Net revenue]]/urbanthreads_q4[[#This Row],[Total]] -> 1 | AB5: =TEXT(urbanthreads_q4[[#This Row],[Order Date]],"mm-yyyy") -> 12-2024 | AC5: =YEAR(urbanthreads_q4[[#This Row],[Order Date]]) & "-W" & WEEKNUM(urbanthreads_q4[[#This Row],[Order Date]], 2) -> 2024-W53 | AD5: =IF(urbanthreads_q4[[#This Row],[Payment]]="COD","COD","Prepaid") -> Prepaid
A6: UT-100005 | B6: 45566 | C6: CUST_10001 | D6: New | E6: ACC-SCF-OS | F6: Accessories | G6: Silk Scarf | H6: 799 | I6: 3 | J6: 2397 | L6: 0 | M6: UPI | N6: Website | O6: Mumbai | P6: Maharashtra | Q6: Mumbai | R6: 45571 | S6: Delivered | T6: No | W6: Not Applicable | X6: =IF(urbanthreads_q4[[#This Row],[Qty]]>0,"Valid","Invalid") -> Valid | Y6: =urbanthreads_q4[[#This Row],[Total]]*urbanthreads_q4[[#This Row],[Disc %]]/100 -> 0 | Z6: =urbanthreads_q4[[#This Row],[Total]]-urbanthreads_q4[[#This Row],[Disc %]] -> 2397 | AA6: =urbanthreads_q4[[#This Row],[Net revenue]]/urbanthreads_q4[[#This Row],[Total]] -> 1 | AB6: =TEXT(urbanthreads_q4[[#This Row],[Order Date]],"mm-yyyy") -> 10-2024 | AC6: =YEAR(urbanthreads_q4[[#This Row],[Order Date]]) & "-W" & WEEKNUM(urbanthreads_q4[[#This Row],[Order Date]], 2) -> 2024-W40 | AD6: =IF(urbanthreads_q4[[#This Row],[Payment]]="COD","COD","Prepaid") -> Prepaid
A7: UT-100346 | B7: 45657 | C7: CUST_10345 | D7: New | E7: DRS-CNT-S | F7: Dresses | G7: Countdown Dress | H7: 4499 | I7: 1 | J7: 4499 | K7: Dec20 | L7: 20 | M7: Credit Card | N7: Website | O7: Noida | P7: Uttar Pradesh | Q7: Delhi | R7: 45685 | S7: Delivered | T7: Yes | U7: Size Issue | V7: 45713 | W7: Processed | X7: =IF(urbanthreads_q4[[#This Row],[Qty]]>0,"Valid","Invalid") -> Valid | Y7: =urbanthreads_q4[[#This Row],[Total]]*urbanthreads_q4[[#This Row],[Disc %]]/100 -> 899.8 | Z7: =urbanthreads_q4[[#This Row],[Total]]-urbanthreads_q4[[#This Row],[Disc %]] -> 4479 | AA7: =urbanthreads_q4[[#This Row],[Net revenue]]/urbanthreads_q4[[#This Row],[Total]] -> 0.99555457 | AB7: =TEXT(urbanthreads_q4[[#This Row],[Order Date]],"mm-yyyy") -> 12-2024 | AC7: =YEAR(urbanthreads_q4[[#This Row],[Order Date]]) & "-W" & WEEKNUM(urbanthreads_q4[[#This Row],[Order Date]], 2) -> 2024-W53 | AD7: =IF(urbanthreads_q4[[#This Row],[Payment]]="COD","COD","Prepaid") -> Prepaid
A8: UT-100007 | B8: 45567 | C8: CUST_10006 | D8: New | E8: DRS-CAS-M | F8: Dresses | G8: A-Line Dress | H8: 2199 | I8: 1 | J8: 2199 | K8: DIWALI20 | L8: 20 | M8: COD | N8: Website | O8: Pune | P8: Maharashtra | Q8: Mumbai | S8: Cancelled | T8: No | W8: Not Applicable | X8: =IF(urbanthreads_q4[[#This Row],[Qty]]>0,"Valid","Invalid") -> Valid | Y8: =urbanthreads_q4[[#This Row],[Total]]*urbanthreads_q4[[#This Row],[Disc %]]/100 -> 439.8 | Z8: =urbanthreads_q4[[#This Row],[Total]]-urbanthreads_q4[[#This Row],[Disc %]] -> 2179 | AA8: =urbanthreads_q4[[#This Row],[Net revenue]]/urbanthreads_q4[[#This Row],[Total]] -> 0.99090496 | AB8: =TEXT(urbanthreads_q4[[#This Row],[Order Date]],"mm-yyyy") -> 10-2024 | AC8: =YEAR(urbanthreads_q4[[#This Row],[Order Date]]) & "-W" & WEEKNUM(urbanthreads_q4[[#This Row],[Order Date]], 2) -> 2024-W40 | AD8: =IF(urbanthreads_q4[[#This Row],[Payment]]="COD","COD","Prepaid") -> COD
A9: UT-100008 | B9: 45567 | C9: CUST_10007 | D9: New | E9: BOT-TRS-L | F9: Bottoms | G9: Formal Trousers | H9: 2299 | I9: 1 | J9: 2299 | L9: 0 | M9: UPI | N9: Mobile App | O9: Kolkata | P9: West Bengal | Q9: Delhi | R9: 45575 | S9: Delivered | T9: No | W9: Not Applicable | X9: =IF(urbanthreads_q4[[#This Row],[Qty]]>0,"Valid","Invalid") -> Valid | Y9: =urbanthreads_q4[[#This Row],[Total]]*urbanthreads_q4[[#This Row],[Disc %]]/100 -> 0 | Z9: =urbanthreads_q4[[#This Row],[Total]]-urbanthreads_q4[[#This Row],[Disc %]] -> 2299 | AA9: =urbanthreads_q4[[#This Row],[Net revenue]]/urbanthreads_q4[[#This Row],[Total]] -> 1 | AB9: =TEXT(urbanthreads_q4[[#This Row],[Order Date]],"mm-yyyy") -> 10-2024 | AC9: =YEAR(urbanthreads_q4[[#This Row],[Order Date]]) & "-W" & WEEKNUM(urbanthreads_q4[[#This Row],[Order Date]], 2) -> 2024-W40 | AD9: =IF(urbanthreads_q4[[#This Row],[Payment]]="COD","COD","Prepaid") -> Prepaid
A10: UT-100315 | B10: 45649 | C10: CUST_10314 | D10: New | E10: TOP-FLK-L | F10: Tops | G10: Snowflake Top | H10: 2199 | I10: 1 | J10: 2199 | L10: 0 | M10: Debit Card | N10: Instagram Shop | O10: Mumbai | P10: Maharashtra | Q10: Mumbai | R10: 45672 | S10: Delivered | T10: Yes | U10: Damaged in Transit | V10: 45699 | W10: Processed | X10: =IF(urbanthreads_q4[[#This Row],[Qty]]>0,"Valid","Invalid") -> Valid | Y10: =urbanthreads_q4[[#This Row],[Total]]*urbanthreads_q4[[#This Row],[Disc %]]/100 -> 0 | Z10: =urbanthreads_q4[[#This Row],[Total]]-urbanthreads_q4[[#This Row],[Disc %]] -> 2199 | AA10: =urbanthreads_q4[[#This Row],[Net revenue]]/urbanthreads_q4[[#This Row],[Total]] -> 1 | AB10: =TEXT(urbanthreads_q4[[#This Row],[Order Date]],"mm-yyyy") -> 12-2024 | AC10: =YEAR(urbanthreads_q4[[#This Row],[Order Date]]) & "-W" & WEEKNUM(urbanthreads_q4[[#This Row],[Order Date]], 2) -> 2024-W52 | AD10: =IF(urbanthreads_q4[[#This Row],[Payment]]="COD","COD","Prepaid") -> Prepaid
A11: UT-100316 | B11: 45649 | C11: CUST_10315 | D11: New | E11: DRS-SPR-S | F11: Dresses | G11: Sparkle Season Dress | H11: 3799 | I11: 1 | J11: 3799 | K11: Dec20 | L11: 20 | M11: Credit Card | N11: Website | O11: Delhi | P11: Delhi | Q11: Delhi | R11: 45673 | S11: Delivered | T11: Yes | U11: Size Issue | V11: 45701 | W11: Processed | X11: =IF(urbanthreads_q4[[#This Row],[Qty]]>0,"Valid","Invalid") -> Valid | Y11: =urbanthreads_q4[[#This Row],[Total]]*urbanthreads_q4[[#This Row],[Disc %]]/100 -> 759.8 | Z11: =urbanthreads_q4[[#This Row],[Total]]-urbanthreads_q4[[#This Row],[Disc %]] -> 3779 | AA11: =urbanthreads_q4[[#This Row],[Net revenue]]/urbanthreads_q4[[#This Row],[Total]] -> 0.99473546 | AB11: =TEXT(urbanthreads_q4[[#This Row],[Order Date]],"mm-yyyy") -> 12-2024 | AC11: =YEAR(urbanthreads_q4[[#This Row],[Order Date]]) & "-W" & WEEKNUM(urbanthreads_q4[[#This Row],[Order Date]], 2) -> 2024-W52 | AD11: =IF(urbanthreads_q4[[#This Row],[Payment]]="COD","COD","Prepaid") -> Prepaid
A12: UT-100011 | B12: 45568 | C12: CUST_10010 | D12: New | E12: ACC-BAG-OS | F12: Accessories | G12: Tote Bag | H12: 1299 | I12: 2 | J12: 2598 | K12: FLAT10 | L12: 10 | M12: Wallet | N12: Website | O12: Lucknow | P12: Uttar Pradesh | Q12: Delhi | R12: 45575 | S12: Delivered | T12: No | W12: Not Applicable | X12: =IF(urbanthreads_q4[[#This Row],[Qty]]>0,"Valid","Invalid") -> Valid | Y12: =urbanthreads_q4[[#This Row],[Total]]*urbanthreads_q4[[#This Row],[Disc %]]/100 -> 259.8 | Z12: =urbanthreads_q4[[#This Row],[Total]]-urbanthreads_q4[[#This Row],[Disc %]] -> 2588 | AA12: =urbanthreads_q4[[#This Row],[Net revenue]]/urbanthreads_q4[[#This Row],[Total]] -> 0.99615089 | AB12: =TEXT(urbanthreads_q4[[#This Row],[Order Date]],"mm-yyyy") -> 10-2024 | AC12: =YEAR(urbanthreads_q4[[#This Row],[Order Date]]) & "-W" & WEEKNUM(urbanthreads_q4[[#This Row],[Order Date]], 2) -> 2024-W40 | AD12: =IF(urbanthreads_q4[[#This Row],[Payment]]="COD","COD","Prepaid") -> Prepaid
A13: UT-100012 | B13: 45568 | C13: CUST_10011 | D13: New | E13: DRS-PRT-S | F13: Dresses | G13: Party Dress | H13: 3299 | I13: 1 | J13: 3299 | L13: 0 | M13: COD | N13: Mobile App | O13: Chandigarh | P13: Punjab | Q13: Delhi | S13: RTO | T13: No | W13: Not Applicable | X13: =IF(urbanthreads_q4[[#This Row],[Qty]]>0,"Valid","Invalid") -> Valid | Y13: =urbanthreads_q4[[#This Row],[Total]]*urbanthreads_q4[[#This Row],[Disc %]]/100 -> 0 | Z13: =urbanthreads_q4[[#This Row],[Total]]-urbanthreads_q4[[#This Row],[Disc %]] -> 3299 | AA13: =urbanthreads_q4[[#This Row],[Net revenue]]/urbanthreads_q4[[#This Row],[Total]] -> 1 | AB13: =TEXT(urbanthreads_q4[[#This Row],[Order Date]],"mm-yyyy") -> 10-2024 | AC13: =YEAR(urbanthreads_q4[[#This Row],[Order Date]]) & "-W" & WEEKNUM(urbanthreads_q4[[#This Row],[Order Date]], 2) -> 2024-W40 | AD13: =IF(urbanthreads_q4[[#This Row],[Payment]]="COD","COD","Prepaid") -> COD
A14: UT-100013 | B14: 45568 | C14: CUST_10012 | D14: Returning | E14: TOP-SLK-M | F14: Tops | G14: Silk Blouse | H14: 2499 | I14: 1 | J14: 2499 | L14: 0 | M14: Credit Card | N14: Website | O14: Mumbai | P14: Maharashtra | Q14: Mumbai | R14: 45574 | S14: Delivered | T14: No | W14: Not Applicable | X14: =IF(urbanthreads_q4[[#This Row],[Qty]]>0,"Valid","Invalid") -> Valid | Y14: =urbanthreads_q4[[#This Row],[Total]]*urbanthreads_q4[[#This Row],[Disc %]]/100 -> 0 | Z14: =urbanthreads_q4[[#This Row],[Total]]-urbanthreads_q4[[#This Row],[Disc %]] -> 2499 | AA14: =urbanthreads_q4[[#This Row],[Net revenue]]/urbanthreads_q4[[#This Row],[Total]] -> 1 | AB14: =TEXT(urbanthreads_q4[[#This Row],[Order Date]],"mm-yyyy") -> 10-2024 | AC14: =YEAR(urbanthreads_q4[[#This Row],[Order Date]]) & "-W" & WEEKNUM(urbanthreads_q4[[#This Row],[Order Date]], 2) -> 2024-W40 | AD14: =IF(urbanthreads_q4[[#This Row],[Payment]]="COD","COD","Prepaid") -> Prepaid
A15: UT-100318 | B15: 45650 | C15: CUST_10317 | D15: New | E15: OUT-XMS-L | F15: Outerwear | G15: Christmas Coat | H15: 6499 | I15: 1 | J15: 6499 | L15: 0 | M15: COD | N15: Instagram Shop | O15: Noida | P15: Uttar Pradesh | Q15: Delhi | R15: 45674 | S15: Delivered | T15: Yes | U15: Changed Mind | V15: 45702 | W15: Processed | X15: =IF(urbanthreads_q4[[#This Row],[Qty]]>0,"Valid","Invalid") -> Valid | Y15: =urbanthreads_q4[[#This Row],[Total]]*urbanthreads_q4[[#This Row],[Disc %]]/100 -> 0 | Z15: =urbanthreads_q4[[#This Row],[Total]]-urbanthreads_q4[[#This Row],[Disc %]] -> 6499 | AA15: =urbanthreads_q4[[#This Row],[Net revenue]]/urbanthreads_q4[[#This Row],[Total]] -> 1 | AB15: =TEXT(urbanthreads_q4[[#This Row],[Order Date]],"mm-yyyy") -> 12-2024 | AC15: =YEAR(urbanthreads_q4[[#This Row],[Order Date]]) & "-W" & WEEKNUM(urbanthreads_q4[[#This Row],[Order Date]], 2) -> 2024-W52 | AD15: =IF(urbanthreads_q4[[#This Row],[Payment]]="COD","COD","Prepaid") -> COD
A16: UT-100015 | B16: 45568 | C16: CUST_10014 | D16: New | E16: OUT-CRD-L | F16: Outerwear | G16: Knit Cardigan | H16: 2799 | I16: 1 | J16: 2799 | L16: 0 | M16: Debit Card | N16: Mobile App | O16: Bangalore | P16: Karnataka | Q16: Bangalore | R16: 45577 | S16: Delivered | T16: No | W16: Not Applicable | X16: =IF(urbanthreads_q4[[#This Row],[Qty]]>0,"Valid","Invalid") -> Valid | Y16: =urbanthreads_q4[[#This Row],[Total]]*urbanthreads_q4[[#This Row],[Disc %]]/100 -> 0 | Z16: =urbanthreads_q4[[#This Row],[Total]]-urbanthreads_q4[[#This Row],[Disc %]] -> 2799 | AA16: =urbanthreads_q4[[#This Row],[Net revenue]]/urbanthreads_q4[[#This Row],[Total]] -> 1 | AB16: =TEXT(urbanthreads_q4[[#This Row],[Order Date]],"mm-yyyy") -> 10-2024 | AC16: =YEAR(urbanthreads_q4[[#This Row],[Order Date]]) & "-W" & WEEKNUM(urbanthreads_q4[[#This Row],[Order Date]], 2) -> 2024-W40 | AD16: =IF(urbanthreads_q4[[#This Row],[Payment]]="COD","COD","Prepaid") -> Prepaid
A17: UT-100320 | B17: 45650 | C17: CUST_10319 | D17: New | E17: TOP-RDR-M | F17: Tops | G17: Reindeer Top | H17: 1799 | I17: 1 | J17: 1799 | L17: 0 | M17: Debit Card | N17: Mobile App | O17: Indore | P17: Madhya Pradesh | Q17: Mumbai | R17: 45674 | S17: Delivered | T17: Yes | U17: Quality Defect | V17: 45701 | W17: Processed | X17: =IF(urbanthreads_q4[[#This Row],[Qty]]>0,"Valid","Invalid") -> Valid | Y17: =urbanthreads_q4[[#This Row],[Total]]*urbanthreads_q4[[#This Row],[Disc %]]/100 -> 0 | Z17: =urbanthreads_q4[[#This Row],[Total]]-urbanthreads_q4[[#This Row],[Disc %]] -> 1799 | AA17: =urbanthreads_q4[[#This Row],[Net revenue]]/urbanthreads_q4[[#This Row],[Total]] -> 1 | AB17: =TEXT(urbanthreads_q4[[#This Row],[Order Date]],"mm-yyyy") -> 12-2024 | AC17: =YEAR(urbanthreads_q4[[#This Row],[Order Date]]) & "-W" & WEEKNUM(urbanthreads_q4[[#This Row],[Order Date]], 2) -> 2024-W52 | AD17: =IF(urbanthreads_q4[[#This Row],[Payment]]="COD","COD","Prepaid") -> Prepaid
A18: UT-100017 | B18: 45569 | C18: CUST_10016 | D18: New | E18: TOP-CRP-XS | F18: Tops | G18: Crop Top | H18: 999 | I18: 1 | J18: 999 | K18: FIRST15 | L18: 15 | M18: UPI | N18: Mobile App | O18: Gurgaon | P18: Haryana | Q18: Delhi | R18: 45577 | S18: Delivered | T18: No | W18: Not Applicable | X18: =IF(urbanthreads_q4[[#This Row],[Qty]]>0,"Valid","Invalid") -> Valid | Y18: =urbanthreads_q4[[#This Row],[Total]]*urbanthreads_q4[[#This Row],[Disc %]]/100 -> 149.85 | Z18: =urbanthreads_q4[[#This Row],[Total]]-urbanthreads_q4[[#This Row],[Disc %]] -> 984 | AA18: =urbanthreads_q4[[#This Row],[Net revenue]]/urbanthreads_q4[[#This Row],[Total]] -> 0.98498498 | AB18: =TEXT(urbanthreads_q4[[#This Row],[Order Date]],"mm-yyyy") -> 10-2024 | AC18: =YEAR(urbanthreads_q4[[#This Row],[Order Date]]) & "-W" & WEEKNUM(urbanthreads_q4[[#This Row],[Order Date]], 2) -> 2024-W40 | AD18: =IF(urbanthreads_q4[[#This Row],[Payment]]="COD","COD","Prepaid") -> Prepaid
A19: UT-100018 | B19: 45569 | C19: CUST_10017 | D19: New | E19: DRS-MAX-M | F19: Dresses | G19: Maxi Dress | H19: 2899 | I19: 1 | J19: 2899 | L19: 0 | M19: Credit Card | N19: Website | O19: Indore | P19: Madhya Pradesh | Q19: Mumbai | R19: 45579 | S19: Delivered | T19: No | W19: Not Applicable | X19: =IF(urbanthreads_q4[[#This Row],[Qty]]>0,"Valid","Invalid") -> Valid | Y19: =urbanthreads_q4[[#This Row],[Total]]*urbanthreads_q4[[#This Row],[Disc %]]/100 -> 0 | Z19: =urbanthreads_q4[[#This Row],[Total]]-urbanthreads_q4[[#This Row],[Disc %]] -> 2899 | AA19: =urbanthreads_q4[[#This Row],[Net revenue]]/urbanthreads_q4[[#This Row],[Total]] -> 1 | AB19: =TEXT(urbanthreads_q4[[#This Row],[Order Date]],"mm-yyyy") -> 10-2024 | AC19: =YEAR(urbanthreads_q4[[#This Row],[Order Date]]) & "-W" & WEEKNUM(urbanthreads_q4[[#This Row],[Order Date]], 2) -> 2024-W40 | AD19: =IF(urbanthreads_q4[[#This Row],[Payment]]="COD","COD","Prepaid") -> Prepaid
A20: UT-100321 | B20: 45650 | C20: CUST_10320 | D20: New | E20: DRS-STR-L | F20: Dresses | G20: Star Bright Dress | H20: 4299 | I20: 1 | J20: 4299 | L20: 0 | M20: Credit Card | N20: Instagram Shop | O20: Surat | P20: Gujarat | Q20: Mumbai | R20: 45675 | S20: Delivered | T20: Yes | U20: Size Issue | V20: 45703 | W20: Processed | X20: =IF(urbanthreads_q4[[#This Row],[Qty]]>0,"Valid","Invalid") -> Valid | Y20: =urbanthreads_q4[[#This Row],[Total]]*urbanthreads_q4[[#This Row],[Disc %]]/100 -> 0 | Z20: =urbanthreads_q4[[#This Row],[Total]]-urbanthreads_q4[[#This Row],[Disc %]] -> 4299 | AA20: =urbanthreads_q4[[#This Row],[Net revenue]]/urbanthreads_q4[[#This Row],[Total]] -> 1 | AB20: =TEXT(urbanthreads_q4[[#This Row],[Order Date]],"mm-yyyy") -> 12-2024 | AC20: =YEAR(urbanthreads_q4[[#This Row],[Order Date]]) & "-W" & WEEKNUM(urbanthreads_q4[[#This Row],[Order Date]], 2) -> 2024-W52 | AD20: =IF(urbanthreads_q4[[#This Row],[Payment]]="COD","COD","Prepaid") -> Prepaid
A21: UT-100020 | B21: 45570 | C21: CUST_10019 | D21: New | E21: OUT-VST-S | F21: Outerwear | G21: Puffer Vest | H21: 3999 | I21: 1 | J21: 3999 | K21: DIWALI20 | L21: 20 | M21: COD | N21: Website | O21: Patna | P21: Bihar | Q21: Delhi | S21: RTO | T21: No | W21: Not Applicable | X21: =IF(urbanthreads_q4[[#This Row],[Qty]]>0,"Valid","Invalid") -> Valid | Y21: =urbanthreads_q4[[#This Row],[Total]]*urbanthreads_q4[[#This Row],[Disc %]]/100 -> 799.8 | Z21: =urbanthreads_q4[[#This Row],[Total]]-urbanthreads_q4[[#This Row],[Disc %]] -> 3979 | AA21: =urbanthreads_q4[[#This Row],[Net revenue]]/urbanthreads_q4[[#This Row],[Total]] -> 0.99499875 | AB21: =TEXT(urbanthreads_q4[[#This Row],[Order Date]],"mm-yyyy") -> 10-2024 | AC21: =YEAR(urbanthreads_q4[[#This Row],[Order Date]]) & "-W" & WEEKNUM(urbanthreads_q4[[#This Row],[Order Date]], 2) -> 2024-W40 | AD21: =IF(urbanthreads_q4[[#This Row],[Payment]]="COD","COD","Prepaid") -> COD
A22: UT-100021 | B22: 45570 | C22: CUST_10020 | D22: New | E22: TOP-TUN-L | F22: Tops | G22: Tunic Top | H22: 1699 | I22: 1 | J22: 1699 | L22: 0 | M22: UPI | N22: Mobile App | O22: Bhopal | P22: Madhya Pradesh | Q22: Mumbai | R22: 45580 | S22: Delivered | T22: No | W22: Not Applicable | X22: =IF(urbanthreads_q4[[#This Row],[Qty]]>0,"Valid","Invalid") -> Valid | Y22: =urbanthreads_q4[[#This Row],[Total]]*urbanthreads_q4[[#This Row],[Disc %]]/100 -> 0 | Z22: =urbanthreads_q4[[#This Row],[Total]]-urbanthreads_q4[[#This Row],[Disc %]] -> 1699 | AA22: =urbanthreads_q4[[#This Row],[Net revenue]]/urbanthreads_q4[[#This Row],[Total]] -> 1 | AB22: =TEXT(urbanthreads_q4[[#This Row],[Order Date]],"mm-yyyy") -> 10-2024 | AC22: =YEAR(urbanthreads_q4[[#This Row],[Order Date]]) & "-W" & WEEKNUM(urbanthreads_q4[[#This Row],[Order Date]], 2) -> 2024-W40 | AD22: =IF(urbanthreads_q4[[#This Row],[Payment]]="COD","COD","Prepaid") -> Prepaid
A23: UT-100323 | B23: 45651 | C23: CUST_10322 | D23: New | E23: OUT-JOL-M | F23: Outerwear | G23: Jolly Jacket | H23: 4999 | I23: 1 | J23: 4999 | L23: 0 | M23: COD | N23: Mobile App | O23: Bhopal | P23: Madhya Pradesh | Q23: Mumbai | R23: 45676 | S23: Delivered | T23: Yes | U23: Wrong Item | V23: 45704 | W23: Processed | X23: =IF(urbanthreads_q4[[#This Row],[Qty]]>0,"Valid","Invalid") -> Valid | Y23: =urbanthreads_q4[[#This Row],[Total]]*urbanthreads_q4[[#This Row],[Disc %]]/100 -> 0 | Z23: =urbanthreads_q4[[#This Row],[Total]]-urbanthreads_q4[[#This Row],[Disc %]] -> 4999 | AA23: =urbanthreads_q4[[#This Row],[Net revenue]]/urbanthreads_q4[[#This Row],[Total]] -> 1 | AB23: =TEXT(urbanthreads_q4[[#This Row],[Order Date]],"mm-yyyy") -> 12-2024 | AC23: =YEAR(urbanthreads_q4[[#This Row],[Order Date]]) & "-W" & WEEKNUM(urbanthreads_q4[[#This Row],[Order Date]], 2) -> 2024-W52 | AD23: =IF(urbanthreads_q4[[#This Row],[Payment]]="COD","COD","Prepaid") -> COD
A24: UT-100023 | B24: 45570 | C24: CUST_10022 | D24: New | E24: ACC-BLT-M | F24: Accessories | G24: Leather Belt | H24: 899 | I24: 1 | J24: 899 | K24: FLAT10 | L24: 10 | M24: Debit Card | N24: Mobile App | O24: Coimbatore | P24: Tamil Nadu | Q24: Bangalore | R24: 45582 | S24: Delivered | T24: No | W24: Not Applicable | X24: =IF(urbanthreads_q4[[#This Row],[Qty]]>0,"Valid","Invalid") -> Valid | Y24: =urbanthreads_q4[[#This Row],[Total]]*urbanthreads_q4[[#This Row],[Disc %]]/100 -> 89.9 | Z24: =urbanthreads_q4[[#This Row],[Total]]-urbanthreads_q4[[#This Row],[Disc %]] -> 889 | AA24: =urbanthreads_q4[[#This Row],[Net revenue]]/urbanthreads_q4[[#This Row],[Total]] -> 0.98887653 | AB24: =TEXT(urbanthreads_q4[[#This Row],[Order Date]],"mm-yyyy") -> 10-2024 | AC24: =YEAR(urbanthreads_q4[[#This Row],[Order Date]]) & "-W" & WEEKNUM(urbanthreads_q4[[#This Row],[Order Date]], 2) -> 2024-W40 | AD24: =IF(urbanthreads_q4[[#This Row],[Payment]]="COD","COD","Prepaid") -> Prepaid
A25: UT-100325 | B25: 45651 | C25: CUST_10324 | D25: New | E25: TOP-HLY-L | F25: Tops | G25: Holly Top | H25: 2099 | I25: 1 | J25: 2099 | K25: Dec20 | L25: 20 | M25: Debit Card | N25: Website | O25: Coimbatore | P25: Tamil Nadu | Q25: Bangalore | R25: 45676 | S25: Delivered | T25: Yes | U25: Damaged in Transit | V25: 45703 | W25: Processed | X25: =IF(urbanthreads_q4[[#This Row],[Qty]]>0,"Valid","Invalid") -> Valid | Y25: =urbanthreads_q4[[#This Row],[Total]]*urbanthreads_q4[[#This Row],[Disc %]]/100 -> 419.8 | Z25: =urbanthreads_q4[[#This Row],[Total]]-urbanthreads_q4[[#This Row],[Disc %]] -> 2079 | AA25: =urbanthreads_q4[[#This Row],[Net revenue]]/urbanthreads_q4[[#This Row],[Total]] -> 0.99047165 | AB25: =TEXT(urbanthreads_q4[[#This Row],[Order Date]],"mm-yyyy") -> 12-2024 | AC25: =YEAR(urbanthreads_q4[[#This Row],[Order Date]]) & "-W" & WEEKNUM(urbanthreads_q4[[#This Row],[Order Date]], 2) -> 2024-W52 | AD25: =IF(urbanthreads_q4[[#This Row],[Payment]]="COD","COD","Prepaid") -> Prepaid
A26: UT-100025 | B26: 45571 | C26: CUST_10024 | D26: New | E26: TOP-PLO-L | F26: Tops | G26: Polo Shirt | H26: 1799 | I26: 2 | J26: 3598 | L26: 0 | M26: UPI | N26: Website | O26: Vizag | P26: Andhra Pradesh | Q26: Bangalore | R26: 45582 | S26: Delivered | T26: No | W26: Not Applicable | X26: =IF(urbanthreads_q4[[#This Row],[Qty]]>0,"Valid","Invalid") -> Valid | Y26: =urbanthreads_q4[[#This Row],[Total]]*urbanthreads_q4[[#This Row],[Disc %]]/100 -> 0 | Z26: =urbanthreads_q4[[#This Row],[Total]]-urbanthreads_q4[[#This Row],[Disc %]] -> 3598 | AA26: =urbanthreads_q4[[#This Row],[Net revenue]]/urbanthreads_q4[[#This Row],[Total]] -> 1 | AB26: =TEXT(urbanthreads_q4[[#This Row],[Order Date]],"mm-yyyy") -> 10-2024 | AC26: =YEAR(urbanthreads_q4[[#This Row],[Order Date]]) & "-W" & WEEKNUM(urbanthreads_q4[[#This Row],[Order Date]], 2) -> 2024-W40 | AD26: =IF(urbanthreads_q4[[#This Row],[Payment]]="COD","COD","Prepaid") -> Prepaid
A27: UT-100026 | B27: 45571 | C27: CUST_10025 | D27: New | E27: DRS-WRK-M | F27: Dresses | G27: Work Dress | H27: 2699 | I27: 1 | J27: 2699 | L27: 0 | M27: Credit Card | N27: Mobile App | O27: Thiruvananthapuram | P27: Kerala | Q27: Bangalore | R27: 45583 | S27: Delivered | T27: No | W27: Not Applicable | X27: =IF(urbanthreads_q4[[#This Row],[Qty]]>0,"Valid","Invalid") -> Valid | Y27: =urbanthreads_q4[[#This Row],[Total]]*urbanthreads_q4[[#This Row],[Disc %]]/100 -> 0 | Z27: =urbanthreads_q4[[#This Row],[Total]]-urbanthreads_q4[[#This Row],[Disc %]] -> 2699 | AA27: =urbanthreads_q4[[#This Row],[Net revenue]]/urbanthreads_q4[[#This Row],[Total]] -> 1 | AB27: =TEXT(urbanthreads_q4[[#This Row],[Order Date]],"mm-yyyy") -> 10-2024 | AC27: =YEAR(urbanthreads_q4[[#This Row],[Order Date]]) & "-W" & WEEKNUM(urbanthreads_q4[[#This Row],[Order Date]], 2) -> 2024-W40 | AD27: =IF(urbanthreads_q4[[#This Row],[Payment]]="COD","COD","Prepaid") -> Prepaid
A28: UT-100326 | B28: 45652 | C28: CUST_10325 | D28: New | E28: DRS-BOX-S | F28: Dresses | G28: Boxing Day Dress | H28: 2999 | I28: 1 | J28: 2999 | L28: 0 | M28: Credit Card | N28: Mobile App | O28: Kochi | P28: Kerala | Q28: Bangalore | R28: 45677 | S28: Delivered | T28: Yes | U28: Size Issue | V28: 45705 | W28: Processed | X28: =IF(urbanthreads_q4[[#This Row],[Qty]]>0,"Valid","Invalid") -> Valid | Y28: =urbanthreads_q4[[#This Row],[Total]]*urbanthreads_q4[[#This Row],[Disc %]]/100 -> 0 | Z28: =urbanthreads_q4[[#This Row],[Total]]-urbanthreads_q4[[#This Row],[Disc %]] -> 2999 | AA28: =urbanthreads_q4[[#This Row],[Net revenue]]/urbanthreads_q4[[#This Row],[Total]] -> 1 | AB28: =TEXT(urbanthreads_q4[[#This Row],[Order Date]],"mm-yyyy") -> 12-2024 | AC28: =YEAR(urbanthreads_q4[[#This Row],[Order Date]]) & "-W" & WEEKNUM(urbanthreads_q4[[#This Row],[Order Date]], 2) -> 2024-W52 | AD28: =IF(urbanthreads_q4[[#This Row],[Payment]]="COD","COD","Prepaid") -> Prepaid
A29: UT-100028 | B29: 45572 | C29: CUST_10027 | D29: New | E29: ACC-HAT-OS | F29: Accessories | G29: Fedora Hat | H29: 1099 | I29: 1 | J29: 1099 | L29: 0 | M29: UPI | N29: Instagram Shop | O29: Vadodara | P29: Gujarat | Q29: Mumbai | R29: 45585 | S29: Delivered | T29: No | W29: Not Applicable | X29: =IF(urbanthreads_q4[[#This Row],[Qty]]>0,"Valid","Invalid") -> Valid | Y29: =urbanthreads_q4[[#This Row],[Total]]*urbanthreads_q4[[#This Row],[Disc %]]/100 -> 0 | Z29: =urbanthreads_q4[[#This Row],[Total]]-urbanthreads_q4[[#This Row],[Disc %]] -> 1099 | AA29: =urbanthreads_q4[[#This Row],[Net revenue]]/urbanthreads_q4[[#This Row],[Total]] -> 1 | AB29: =TEXT(urbanthreads_q4[[#This Row],[Order Date]],"mm-yyyy") -> 10-2024 | AC29: =YEAR(urbanthreads_q4[[#This Row],[Order Date]]) & "-W" & WEEKNUM(urbanthreads_q4[[#This Row],[Order Date]], 2) -> 2024-W41 | AD29: =IF(urbanthreads_q4[[#This Row],[Payment]]="COD","COD","Prepaid") -> Prepaid
A30: UT-100029 | B30: 45572 | C30: CUST_10028 | D30: New | E30: TOP-DNM-M | F30: Tops | G30: Denim Shirt | H30: 1899 | I30: 1 | J30: 1899 | L30: 0 | M30: COD | N30: Mobile App | O30: Rajkot | P30: Gujarat | Q30: Mumbai | S30: RTO | T30: No | W30: Not Applicable | X30: =IF(urbanthreads_q4[[#This Row],[Qty]]>0,"Valid","Invalid") -> Valid | Y30: =urbanthreads_q4[[#This Row],[Total]]*urbanthreads_q4[[#This Row],[Disc %]]/100 -> 0 | Z30: =urbanthreads_q4[[#This Row],[Total]]-urbanthreads_q4[[#This Row],[Disc %]] -> 1899 | AA30: =urbanthreads_q4[[#This Row],[Net revenue]]/urbanthreads_q4[[#This Row],[Total]] -> 1 | AB30: =TEXT(urbanthreads_q4[[#This Row],[Order Date]],"mm-yyyy") -> 10-2024 | AC30: =YEAR(urbanthreads_q4[[#This Row],[Order Date]]) & "-W" & WEEKNUM(urbanthreads_q4[[#This Row],[Order Date]], 2) -> 2024-W41 | AD30: =IF(urbanthreads_q4[[#This Row],[Payment]]="COD","COD","Prepaid") -> COD
A31: UT-100030 | B31: 45572 | C31: CUST_10029 | D31: New | E31: BOT-CRG-L | F31: Bottoms | G31: Cargo Pants | H31: 2199 | I31: 1 | J31: 2199 | K31: DIWALI20 | L31: 20 | M31: Credit Card | N31: Website | O31: Kanpur | P31: Uttar Pradesh | Q31: Delhi | R31: 45585 | S31: Delivered | T31: No | W31: Not Applicable | X31: =IF(urbanthreads_q4[[#This Row],[Qty]]>0,"Valid","Invalid") -> Valid | Y31: =urbanthreads_q4[[#This Row],[Total]]*urbanthreads_q4[[#This Row],[Disc %]]/100 -> 439.8 | Z31: =urbanthreads_q4[[#This Row],[Total]]-urbanthreads_q4[[#This Row],[Disc %]] -> 2179 | AA31: =urbanthreads_q4[[#This Row],[Net revenue]]/urbanthreads_q4[[#This Row],[Total]] -> 0.99090496 | AB31: =TEXT(urbanthreads_q4[[#This Row],[Order Date]],"mm-yyyy") -> 10-2024 | AC31: =YEAR(urbanthreads_q4[[#This Row],[Order Date]]) & "-W" & WEEKNUM(urbanthreads_q4[[#This Row],[Order Date]], 2) -> 2024-W41 | AD31: =IF(urbanthreads_q4[[#This Row],[Payment]]="COD","COD","Prepaid") -> Prepaid
A32: UT-100328 | B32: 45652 | C32: CUST_10327 | D32: New | E32: OUT-SAL-L | F32: Outerwear | G32: Sale Special Coat | H32: 5999 | I32: 1 | J32: 5999 | K32: Dec20 | L32: 20 | M32: COD | N32: Website | O32: Thiruvananthapuram | P32: Kerala | Q32: Bangalore | R32: 45678 | S32: Delivered | T32: Yes | U32: Changed Mind | V32: 45706 | W32: Processed | X32: =IF(urbanthreads_q4[[#This Row],[Qty]]>0,"Valid","Invalid") -> Valid | Y32: =urbanthreads_q4[[#This Row],[Total]]*urbanthreads_q4[[#This Row],[Disc %]]/100 -> 1199.8 | Z32: =urbanthreads_q4[[#This Row],[Total]]-urbanthreads_q4[[#This Row],[Disc %]] -> 5979 | AA32: =urbanthreads_q4[[#This Row],[Net revenue]]/urbanthreads_q4[[#This Row],[Total]] -> 0.99666611 | AB32: =TEXT(urbanthreads_q4[[#This Row],[Order Date]],"mm-yyyy") -> 12-2024 | AC32: =YEAR(urbanthreads_q4[[#This Row],[Order Date]]) & "-W" & WEEKNUM(urbanthreads_q4[[#This Row],[Order Date]], 2) -> 2024-W52 | AD32: =IF(urbanthreads_q4[[#This Row],[Payment]]="COD","COD","Prepaid") -> COD
A33: UT-100032 | B33: 45573 | C33: CUST_10031 | D33: New | E33: TOP-BAS-M | F33: Tops | G33: Basic Tank | H33: 899 | I33: 2 | J33: 1798 | L33: 0 | M33: UPI | N33: Website | O33: Delhi | P33: Delhi | Q33: Delhi | R33: 45579 | S33: Delivered | T33: No | W33: Not Applicable | X33: =IF(urbanthreads_q4[[#This Row],[Qty]]>0,"Valid","Invalid") -> Valid | Y33: =urbanthreads_q4[[#This Row],[Total]]*urbanthreads_q4[[#This Row],[Disc %]]/100 -> 0 | Z33: =urbanthreads_q4[[#This Row],[Total]]-urbanthreads_q4[[#This Row],[Disc %]] -> 1798 | AA33: =urbanthreads_q4[[#This Row],[Net revenue]]/urbanthreads_q4[[#This Row],[Total]] -> 1 | AB33: =TEXT(urbanthreads_q4[[#This Row],[Order Date]],"mm-yyyy") -> 10-2024 | AC33: =YEAR(urbanthreads_q4[[#This Row],[Order Date]]) & "-W" & WEEKNUM(urbanthreads_q4[[#This Row],[Order Date]], 2) -> 2024-W41 | AD33: =IF(urbanthreads_q4[[#This Row],[Payment]]="COD","COD","Prepaid") -> Prepaid
A34: UT-100329 | B34: 45652 | C34: CUST_10328 | D34: Returning | E34: ACC-DIS-OS | F34: Accessories | G34: Discount Find Bag | H34: 1299 | I34: 1 | J34: 1299 | L34: 0 | M34: Wallet | N34: Mobile App | O34: Mysore | P34: Karnataka | Q34: Bangalore | R34: 45677 | S34: Delivered | T34: Yes | U34: Quality Defect | V34: 45704 | W34: Processed | X34: =IF(urbanthreads_q4[[#This Row],[Qty]]>0,"Valid","Invalid") -> Valid | Y34: =urbanthreads_q4[[#This Row],[Total]]*urbanthreads_q4[[#This Row],[Disc %]]/100 -> 0 | Z34: =urbanthreads_q4[[#This Row],[Total]]-urbanthreads_q4[[#This Row],[Disc %]] -> 1299 | AA34: =urbanthreads_q4[[#This Row],[Net revenue]]/urbanthreads_q4[[#This Row],[Total]] -> 1 | AB34: =TEXT(urbanthreads_q4[[#This Row],[Order Date]],"mm-yyyy") -> 12-2024 | AC34: =YEAR(urbanthreads_q4[[#This Row],[Order Date]]) & "-W" & WEEKNUM(urbanthreads_q4[[#This Row],[Order Date]], 2) -> 2024-W52 | AD34: =IF(urbanthreads_q4[[#This Row],[Payment]]="COD","COD","Prepaid") -> Prepaid
A35: UT-100034 | B35: 45573 | C35: CUST_10033 | D35: Returning | E35: ACC-WCH-OS | F35: Accessories | G35: Fashion Watch | H35: 2999 | I35: 1 | J35: 2999 | L35: 0 | M35: Credit Card | N35: Mobile App | O35: Chennai | P35: Tamil Nadu | Q35: Bangalore | R35: 45580 | S35: Delivered | T35: No | W35: Not Applicable | X35: =IF(urbanthreads_q4[[#This Row],[Qty]]>0,"Valid","Invalid") -> Valid | Y35: =urbanthreads_q4[[#This Row],[Total]]*urbanthreads_q4[[#This Row],[Disc %]]/100 -> 0 | Z35: =urbanthreads_q4[[#This Row],[Total]]-urbanthreads_q4[[#This Row],[Disc %]] -> 2999 | AA35: =urbanthreads_q4[[#This Row],[Net revenue]]/urbanthreads_q4[[#This Row],[Total]] -> 1 | AB35: =TEXT(urbanthreads_q4[[#This Row],[Order Date]],"mm-yyyy") -> 10-2024 | AC35: =YEAR(urbanthreads_q4[[#This Row],[Order Date]]) & "-W" & WEEKNUM(urbanthreads_q4[[#This Row],[Order Date]], 2) -> 2024-W41 | AD35: =IF(urbanthreads_q4[[#This Row],[Payment]]="COD","COD","Prepaid") -> Prepaid
A36: UT-100331 | B36: 45653 | C36: CUST_10330 | D36: New | E36: DRS-END-L | F36: Dresses | G36: Year End Dress | H36: 3499 | I36: 1 | J36: 3499 | K36: Dec20 | L36: 20 | M36: Credit Card | N36: Website | O36: Rajkot | P36: Gujarat | Q36: Mumbai | R36: 45679 | S36: Delivered | T36: Yes | U36: Size Issue | V36: 45707 | W36: Processed | X36: =IF(urbanthreads_q4[[#This Row],[Qty]]>0,"Valid","Invalid") -> Valid | Y36: =urbanthreads_q4[[#This Row],[Total]]*urbanthreads_q4[[#This Row],[Disc %]]/100 -> 699.8 | Z36: =urbanthreads_q4[[#This Row],[Total]]-urbanthreads_q4[[#This Row],[Disc %]] -> 3479 | AA36: =urbanthreads_q4[[#This Row],[Net revenue]]/urbanthreads_q4[[#This Row],[Total]] -> 0.99428408 | AB36: =TEXT(urbanthreads_q4[[#This Row],[Order Date]],"mm-yyyy") -> 12-2024 | AC36: =YEAR(urbanthreads_q4[[#This Row],[Order Date]]) & "-W" & WEEKNUM(urbanthreads_q4[[#This Row],[Order Date]], 2) -> 2024-W52 | AD36: =IF(urbanthreads_q4[[#This Row],[Payment]]="COD","COD","Prepaid") -> Prepaid
A37: UT-100036 | B37: 45574 | C37: CUST_10035 | D37: New | E37: DRS-SUN-M | F37: Dresses | G37: Sundress | H37: 1999 | I37: 1 | J37: 1999 | K37: DIWALI20 | L37: 20 | M37: Wallet | N37: Mobile App | O37: Pune | P37: Maharashtra | Q37: Mumbai | R37: 45581 | S37: Delivered | T37: No | W37: Not Applicable | X37: =IF(urbanthreads_q4[[#This Row],[Qty]]>0,"Valid","Invalid") -> Valid | Y37: =urbanthreads_q4[[#This Row],[Total]]*urbanthreads_q4[[#This Row],[Disc %]]/100 -> 399.8 | Z37: =urbanthreads_q4[[#This Row],[Total]]-urbanthreads_q4[[#This Row],[Disc %]] -> 1979 | AA37: =urbanthreads_q4[[#This Row],[Net revenue]]/urbanthreads_q4[[#This Row],[Total]] -> 0.989995 | AB37: =TEXT(urbanthreads_q4[[#This Row],[Order Date]],"mm-yyyy") -> 10-2024 | AC37: =YEAR(urbanthreads_q4[[#This Row],[Order Date]]) & "-W" & WEEKNUM(urbanthreads_q4[[#This Row],[Order Date]], 2) -> 2024-W41 | AD37: =IF(urbanthreads_q4[[#This Row],[Payment]]="COD","COD","Prepaid") -> Prepaid
A38: UT-100333 | B38: 45653 | C38: CUST_10332 | D38: New | E38: OUT-LST-M | F38: Outerwear | G38: Last Chance Jacket | H38: 4599 | I38: 1 | J38: 4599 | L38: 0 | M38: COD | N38: Instagram Shop | O38: Mumbai | P38: Maharashtra | Q38: Mumbai | R38: 45680 | S38: Delivered | T38: Yes | U38: Wrong Item | V38: 45708 | W38: Processed | X38: =IF(urbanthreads_q4[[#This Row],[Qty]]>0,"Valid","Invalid") -> Valid | Y38: =urbanthreads_q4[[#This Row],[Total]]*urbanthreads_q4[[#This Row],[Disc %]]/100 -> 0 | Z38: =urbanthreads_q4[[#This Row],[Total]]-urbanthreads_q4[[#This Row],[Disc %]] -> 4599 | AA38: =urbanthreads_q4[[#This Row],[Net revenue]]/urbanthreads_q4[[#This Row],[Total]] -> 1 | AB38: =TEXT(urbanthreads_q4[[#This Row],[Order Date]],"mm-yyyy") -> 12-2024 | AC38: =YEAR(urbanthreads_q4[[#This Row],[Order Date]]) & "-W" & WEEKNUM(urbanthreads_q4[[#This Row],[Order Date]], 2) -> 2024-W52 | AD38: =IF(urbanthreads_q4[[#This Row],[Payment]]="COD","COD","Prepaid") -> COD
A39: UT-100038 | B39: 45574 | C39: CUST_10037 | D39: Returning | E39: OUT-LTH-M | F39: Outerwear | G39: Leather Jacket | H39: 7999 | I39: 1 | J39: 7999 | L39: 0 | M39: Credit Card | N39: Website | O39: Jaipur | P39: Rajasthan | Q39: Delhi | R39: 45583 | S39: Delivered | T39: No | W39: Not Applicable | X39: =IF(urbanthreads_q4[[#This Row],[Qty]]>0,"Valid","Invalid") -> Valid | Y39: =urbanthreads_q4[[#This Row],[Total]]*urbanthreads_q4[[#This Row],[Disc %]]/100 -> 0 | Z39: =urbanthreads_q4[[#This Row],[Total]]-urbanthreads_q4[[#This Row],[Disc %]] -> 7999 | AA39: =urbanthreads_q4[[#This Row],[Net revenue]]/urbanthreads_q4[[#This Row],[Total]] -> 1 | AB39: =TEXT(urbanthreads_q4[[#This Row],[Order Date]],"mm-yyyy") -> 10-2024 | AC39: =YEAR(urbanthreads_q4[[#This Row],[Order Date]]) & "-W" & WEEKNUM(urbanthreads_q4[[#This Row],[Order Date]], 2) -> 2024-W41 | AD39: =IF(urbanthreads_q4[[#This Row],[Payment]]="COD","COD","Prepaid") -> Prepaid
A40: UT-100039 | B40: 45574 | C40: CUST_10038 | D40: New | E40: ACC-SNG-OS | F40: Accessories | G40: Sunglasses | H40: 1499 | I40: 1 | J40: 1499 | K40: FLAT10 | L40: 10 | M40: Debit Card | N40: Mobile App | O40: Lucknow | P40: Uttar Pradesh | Q40: Delhi | R40: 45582 | S40: Delivered | T40: No | W40: Not Applicable | X40: =IF(urbanthreads_q4[[#This Row],[Qty]]>0,"Valid","Invalid") -> Valid | Y40: =urbanthreads_q4[[#This Row],[Total]]*urbanthreads_q4[[#This Row],[Disc %]]/100 -> 149.9 | Z40: =urbanthreads_q4[[#This Row],[Total]]-urbanthreads_q4[[#This Row],[Disc %]] -> 1489 | AA40: =urbanthreads_q4[[#This Row],[Net revenue]]/urbanthreads_q4[[#This Row],[Total]] -> 0.99332889 | AB40: =TEXT(urbanthreads_q4[[#This Row],[Order Date]],"mm-yyyy") -> 10-2024 | AC40: =YEAR(urbanthreads_q4[[#This Row],[Order Date]]) & "-W" & WEEKNUM(urbanthreads_q4[[#This Row],[Order Date]], 2) -> 2024-W41 | AD40: =IF(urbanthreads_q4[[#This Row],[Payment]]="COD","COD","Prepaid") -> Prepaid
...

Sheet Cleaning_log
A1: Issue Type | B1: Column Name | C1: Example | D1: Why | E1: Expected or Error | F1: Action
A2: Missing Value | B2: Deivery_date | C2: RTO orders | D2: Delivery never completed | E2: Expected | F2: Left Blank
A3: Missing Value | B3: Return_reason | C3: RTO orders | D3: RTO orders never reach customers,so no returns exist | E3: Expected | F3: Left Blank
A4: Missing Value | B4: Return_recieved | C4: RTO orders | D4: Items returned to warehouse without customer return | E4: Expected | F4: Left Blank
A5: Duplicate Check | B5: Order ID | C5: All Rows | D5: Each order_id is unique | E5: Expected | F5: No action Needed
A6: Format Inconsistency | B6: Delivery Status | C6: "Delievered" | D6: Typo error | E6: Error | F6: Fixed the typo mistake with find and replace method
A7: Format Check | B7: Multiple text columns | C7: delivery_status,payment_method etc | D7: Checked for spelling,spaces etc | E7: Expected | F7: No futher action needed
A8: Outlier Issue | B8: Quantity | C8: -1 | D8: Quantity cannot be in negative | E8: Error | F8: Flagged and excluded from KPI calculations
A9: Outlier / Logical issue | B9: Quantity

Sheet Validation_summary
A1: Rule ID | B1: Validation Check | C1: Result | D1: Notes
A2: V1 | B2: order_id format UT-XXXXXX | C2: Pass | D2: All IDs consistent
A3: V2 | B3: customer_type values | C3: Pass | D3: New / Returning only
A4: V3 | B4: quantity positive integer | C4: Fail | D4: -1 flagged & excluded
A5: V4 | B5: discount_percent 0–100 | C5: Pass | D5: No outliers
A6: V5 | B6: order_date in Q4 2024 | C6: Pass | D6: All dates in range
A7: V6 | B7: payment_method valid | C7: Pass | D7: No invalid methods
A8: V7 | B8: Delivered → delivery_date | C8: Pass | D8: No missing dates
A9: V8 | B9: No return → blank reason | C9: Pass | D9: Business logic OK
A10: V9 | B10: warehouse_origin valid | C10: Pass | D10: Mumbai/Delhi/Bangalore
A11: V10 | B11: refund_status logic | C11: Pass | D11: Consistent

Sheet Working_Analysis
A3: Row Labels | B3: Count of Order ID | D3: Row Labels | E3: Sum of Discount_amount
A4: Valid | B4: 345 | D4: Valid | E4: 114181.65
A5: Grand Total | B5: 345 | D5: Grand Total | E5: 114181.65
A7: Row Labels | B7: Sum of Qty
A8: Valid | B8: 410 | D8: Row Labels | E8: Count of Order ID
A9: Grand Total | B9: 410 | D9: Valid
D10: Delivered | E10: 327
A11: Row Labels | B11: Sum of Total | D11: Grand Total | E11: 327
A12: Valid | B12: 1018790
A13: Grand Total | B13: 1018790 | D13: Total Delivered Orders | E13: =COUNTIFS(urbanthreads_q4[Status],"Delivered") -> 328 | F13: (Overall Return Rate)
D14: Returned Delivered Orders | E14: =COUNTIFS( urbanthreads_q4[Status], "Delivered", urbanthreads_q4[Return?], "Yes" ) -> 180
D15: Order Return Rate | E15: =E14/E13 -> 0.54878049
D17: Row Labels | E17: Count of Order ID | F17: (Monthly order volume)
D18: 01-2024 | E18: 1
D19: 10-2024 | E19: 131
D20: 11-2024 | E20: 93
D21: 12-2024 | E21: 121 | J21: Status | K21: Delivered
D22: Grand Total | E22: 346 | G22: Status | H22: Delivered | J22: Return? | K22: Yes
D23: Weekly Trend Analysis
D24: Week Number | E24: Total Orders (By week) | G24: Week Number | H24: Total Orders Delivered | J24: Week Number | K24: Returned Delivered Orders
D25: 2024-W2 | E25: 1 | G25: 2024-W2 | H25: 1 | J25: 2024-W40 | K25: 11
D26: 2024-W40 | E26: 26 | G26: 2024-W40 | H26: 23 | J26: 2024-W41 | K26: 11
D27: 2024-W41 | E27: 29 | G27: 2024-W41 | H27: 27 | J27: 2024-W42 | K27: 13
D28: 2024-W42 | E28: 28 | G28: 2024-W42 | H28: 26 | J28: 2024-W43 | K28: 10
D29: 2024-W43 | E29: 27 | G29: 2024-W43 | H29: 24 | J29: 2024-W44 | K29: 24
D30: 2024-W44 | E30: 33 | F30: (Diwali spike -Yes) | G30: 2024-W44 | H30: 31 | J30: 2024-W45 | K30: 11
D31: 2024-W45 | E31: 21 | G31: 2024-W45 | H31: 20 | J31: 2024-W46 | K31: 12
D32: 2024-W46 | E32: 21 | G32: 2024-W46 | H32: 20 | J32: 2024-W47 | K32: 11
D33: 2024-W47 | E33: 21 | G33: 2024-W47 | H33: 20 | J33: 2024-W48 | K33: 13
D34: 2024-W48 | E34: 22 | G34: 2024-W48 | H34: 21 | J34: 2024-W49 | K34: 11
D35: 2024-W49 | E35: 28 | G35: 2024-W49 | H35: 27 | J35: 2024-W50 | K35: 16
D36: 2024-W50 | E36: 28 | G36: 2024-W50 | H36: 27 | J36: 2024-W51 | K36: 17
D37: 2024-W51 | E37: 28 | G37: 2024-W51 | H37: 28 | J37: 2024-W52 | K37: 17
D38: 2024-W52 | E38: 28 | G38: 2024-W52 | H38: 28 | J38: 2024-W53 | K38: 3
D39: 2024-W53 | E39: 5 | G39: 2024-W53 | H39: 5 | J39: Grand Total | K39: 180
D40: Grand Total | E40: 346 | G40: Grand Total | H40: 328
D42: Segmentation Analysis
H43: Segment A (Customer Type)
D44: Row Labels | E44: Order volume by customer type | G44: Row Labels | H44: Order volume by customer type | I44: Sum of Net revenue | K44: Delivered Orders (New customers) | L44: =COUNTIFS( urbanthreads_q4[Type], "New", urbanthreads_q4[Status], "Delivered" ) -> 253
D45: New | E45: 270 | G45: New | H45: 270 | I45: 786744 | K45: Returned Delivered Orders (New customers) | L45: =COUNTIFS( urbanthreads_q4[Type], "New", urbanthreads_q4[Status], "Delivered", urbanthreads_q4[Return?], "Yes" ) -> 147
...

Sheet Analysis
I1: Descriptive Analysis
I3: Summary(Final Values)
I4: Metric | J4: Value
I5: Total Orders | J5: =COUNTA(urbanthreads_q4[Order ID]) -> 346
I6: Total Revenue (After Discounts) | J6: =SUM(urbanthreads_q4[Net revenue]) -> 1020419
I7: Total Units Sold | J7: =SUM(urbanthreads_q4[Qty]) -> 409
I8: Average Order Value (AOV) | J8: =SUM(urbanthreads_q4[Net revenue]) / COUNTA(urbanthreads_q4[Order ID]) -> 2949.1879
I9: Overall Return Rate | J9: =Working_Analysis!E14/Working_Analysis!E13 -> 0.54878049
I11: Monthly Order Breakdown(Final Values)
I12: Month | J12: Orders
I13: 45566 | J13: =COUNTIFS(urbanthreads_q4[Order Date],">=01-10-2024",urbanthreads_q4[Order Date],"<=31-10-2024") -> 131
I14: 45597 | J14: =COUNTIFS( urbanthreads_q4[Order Date],">=01-11-2024", urbanthreads_q4[Order Date],"<=30-11-2024" ) -> 93
I15: 45627 | J15: =COUNTIFS(urbanthreads_q4[Order Date],">=01-12-2024",urbanthreads_q4[Order Date],"<=31-12-2024") -> 121
I16: Total(Valid Orders) | J16: =SUM(J13:J15) -> 345
I18: TREND IDENTIFICATION(Weekly)
F19: {=Working_Analysis!D24:E40} -> Week Number | G19: Total Orders (By week) | I19: {=Working_Analysis!G24:H40} -> Week Number | J19: Total Orders Delivered | L19: {=Working_Analysis!J24:K39} -> Week Number | M19: Returned Delivered Orders
F20: 2024-W2 | G20: 1 | I20: 2024-W2 | J20: 1 | L20: 2024-W40 | M20: 11
F21: 2024-W40 | G21: 26 | I21: 2024-W40 | J21: 23 | L21: 2024-W41 | M21: 11
F22: 2024-W41 | G22: 29 | I22: 2024-W41 | J22: 27 | L22: 2024-W42 | M22: 13
F23: 2024-W42 | G23: 28 | I23: 2024-W42 | J23: 26 | L23: 2024-W43 | M23: 10
F24: 2024-W43 | G24: 27 | I24: 2024-W43 | J24: 24 | L24: 2024-W44 | M24: 24
F25: 2024-W44 | G25: 33 | H25: (Diwali Spike Week) | I25: 2024-W44 | J25: 31 | L25: 2024-W45 | M25: 11
F26: 2024-W45 | G26: 21 | I26: 2024-W45 | J26: 20 | L26: 2024-W46 | M26: 12
F27: 2024-W46 | G27: 21 | I27: 2024-W46 | J27: 20 | L27: 2024-W47 | M27: 11
F28: 2024-W47 | G28: 21 | I28: 2024-W47 | J28: 20 | L28: 2024-W48 | M28: 13
F29: 2024-W48 | G29: 22 | I29: 2024-W48 | J29: 21 | L29: 2024-W49 | M29: 11
F30: 2024-W49 | G30: 28 | I30: 2024-W49 | J30: 27 | L30: 2024-W50 | M30: 16
F31: 2024-W50 | G31: 28 | I31: 2024-W50 | J31: 27 | L31: 2024-W51 | M31: 17
F32: 2024-W51 | G32: 28 | I32: 2024-W51 | J32: 28 | L32: 2024-W52 | M32: 17
F33: 2024-W52 | G33: 28 | I33: 2024-W52 | J33: 28 | L33: 2024-W53 | M33: 3
F34: 2024-W53 | G34: 5 | I34: 2024-W53 | J34: 5 | L34: Grand Total | M34: 180
F35: Grand Total | G35: 346 | I35: Grand Total | J35: 328
I37: Segmentation Analysis
F38: Segment A — Customer Type
F39: Customer Type | G39: Orders | H39: AOV | I39: Return Rate
F40: New | G40: =COUNTIFS(urbanthreads_q4[Type],"New") -> 270 | H40: =SUMIFS(urbanthreads_q4[Net revenue],urbanthreads_q4[Type],"New") / COUNTIFS(urbanthreads_q4[Type],"New") -> 2913.8667 | I40: =Working_Analysis!E50 -> 0.58102767
F41: Returning | G41: =COUNTIFS(urbanthreads_q4[Type],"Returning") -> 76 | H41: =SUMIFS(urbanthreads_q4[Net revenue],urbanthreads_q4[Type],"Returning") / COUNTIFS(urbanthreads_q4[Type],"Returning") -> 3074.6711 | I41: =Working_Analysis!E51 -> 0.44
F43: Segment B — Order Source
F44: Source | G44: Orders | H44: AOV | I44: Return Rate
F45: Instagram Shop | G45: =COUNTIFS(urbanthreads_q4[Source],"Instagram Shop") -> 109 | H45: =SUMIFS(urbanthreads_q4[Net revenue],urbanthreads_q4[Source],"Instagram Shop") / COUNTIFS(urbanthreads_q4[Source],"Instagram Shop") -> 3069.5963 | I45: =Working_Analysis!E60 -> 0.67619048
...

Sheet Visualization
D1: Urban Threads Q4 2024 — Returns & Fulfillment Performance Dashboard

Sheet Recommendations
I1: Recommendations
